<?xml version='1.0' encoding='us-ascii'?>
<robot name="fr3v2">
  
  
  
  
  
  
  <link name="base">
      </link>
  <joint name="fr3v2_base_joint" type="fixed">
    <parent link="base" />
    <child link="fr3v2_link0" />
    <origin rpy="0 0 0" xyz="0 0 0" />
  </joint>
  
  <link name="fr3v2_link0">
    <inertial>
      <origin rpy="0 0 0" xyz="-0.017200 0.000400 0.074500" />
      <mass value="3.85" />
      <inertia ixx="0.009" ixy="0.0" ixz="0.002" iyy="0.0115" iyz="0.0" izz="0.0085" />
    </inertial>
  </link>
  
  <link name="fr3v2_link1">
    <inertial>
      <origin rpy="0 0 0" xyz="-0.004580 0.027016 -0.061800" />
      <mass value="2.4377" />
      <inertia ixx="0.02324" ixy="0.000333" ixz="-0.000676" iyy="0.02146" iyz="0.003739" izz="0.0055" />
    </inertial>
  </link>
  <joint name="fr3v2_joint1" type="revolute">
    <origin rpy="0 0 0" xyz="0 0 0.333" />
    <parent link="fr3v2_link0" />
    <child link="fr3v2_link1" />
    <axis xyz="0 0 1" />
    <limit effort="87.0" lower="-2.7437" upper="2.7437" velocity="2.62" />
    <safety_controller k_position="100.0" k_velocity="40.0" soft_lower_limit="-2.7437" soft_upper_limit="2.7437" />
    <dynamics D="1" K="7000" damping="0.003" friction="0.2" mu_coulomb="0" mu_viscous="16" />
  </joint>
  
  <link name="fr3v2_link2">
    <inertial>
      <origin rpy="0 0 0" xyz="-0.003473 -0.168509 -0.010479" />
      <mass value="2.2375" />
      <inertia ixx="0.019026" ixy="0.001241" ixz="0.000499" iyy="0.00566" iyz="-0.001804" izz="0.017114" />
    </inertial>
  </link>
  <joint name="fr3v2_joint2" type="revolute">
    <origin rpy="-1.570796326794897 0 0" xyz="0 0 0" />
    <parent link="fr3v2_link1" />
    <child link="fr3v2_link2" />
    <axis xyz="0 0 1" />
    <limit effort="87.0" lower="-1.7837" upper="1.7837" velocity="2.62" />
    <safety_controller k_position="100.0" k_velocity="40.0" soft_lower_limit="-1.7837" soft_upper_limit="1.7837" />
    <dynamics D="1" K="7000" damping="0.003" friction="0.2" mu_coulomb="0" mu_viscous="16" />
  </joint>
  
  <link name="fr3v2_link3">
    <inertial>
      <origin rpy="0 0 0" xyz="0.092968 0.018010 0.033533" />
      <mass value="2.185794" />
      <inertia ixx="0.010225" ixy="0.001144" ixz="0.003497" iyy="0.012398" iyz="0.002156" izz="0.006877" />
    </inertial>
  </link>
  <joint name="fr3v2_joint3" type="revolute">
    <origin rpy="1.570796326794897 0 0" xyz="0 -0.316 0" />
    <parent link="fr3v2_link2" />
    <child link="fr3v2_link3" />
    <axis xyz="0 0 1" />
    <limit effort="87.0" lower="-2.9007" upper="2.9007" velocity="2.62" />
    <safety_controller k_position="100.0" k_velocity="40.0" soft_lower_limit="-2.9007" soft_upper_limit="2.9007" />
    <dynamics D="1" K="7000" damping="0.003" friction="0.2" mu_coulomb="0" mu_viscous="16" />
  </joint>
  
  <link name="fr3v2_link4">
    <inertial>
      <origin rpy="0 0 0" xyz="-0.068745 0.092947 0.011195" />
      <mass value="2.175867" />
      <inertia ixx="0.008878" ixy="-0.003749" ixz="0.001139" iyy="0.007628" iyz="-0.00046" izz="0.010295" />
    </inertial>
  </link>
  <joint name="fr3v2_joint4" type="revolute">
    <origin rpy="1.570796326794897 0 0" xyz="0.0825 0 0" />
    <parent link="fr3v2_link3" />
    <child link="fr3v2_link4" />
    <axis xyz="0 0 1" />
    <limit effort="87.0" lower="-3.0421" upper="-0.1518" velocity="2.62" />
    <safety_controller k_position="100.0" k_velocity="40.0" soft_lower_limit="-3.0421" soft_upper_limit="-0.1518" />
    <dynamics D="1" K="7000" damping="0.003" friction="0.2" mu_coulomb="0" mu_viscous="16" />
  </joint>
  
  <link name="fr3v2_link5">
    <inertial>
      <origin rpy="0 0 0" xyz="-0.004197 0.010257 -0.058103" />
      <mass value="2.174817" />
      <inertia ixx="0.031874" ixy="0.000134" ixz="-0.000265" iyy="0.029674" iyz="-0.004734" izz="0.004751" />
    </inertial>
  </link>
  <joint name="fr3v2_joint5" type="revolute">
    <origin rpy="-1.570796326794897 0 0" xyz="-0.0825 0.384 0" />
    <parent link="fr3v2_link4" />
    <child link="fr3v2_link5" />
    <axis xyz="0 0 1" />
    <limit effort="12.0" lower="-2.8065" upper="2.8065" velocity="5.26" />
    <safety_controller k_position="100.0" k_velocity="40.0" soft_lower_limit="-2.8065" soft_upper_limit="2.8065" />
    <dynamics D="1" K="7000" damping="0.003" friction="0.2" mu_coulomb="0" mu_viscous="16" />
  </joint>
  
  <link name="fr3v2_link6">
    <inertial>
      <origin rpy="0 0 0" xyz="0.070958 -0.014137 -0.035324" />
      <mass value="1.567617" />
      <inertia ixx="0.00286" ixy="-0.000553" ixz="-0.000638" iyy="0.00391" iyz="-0.00024" izz="0.00453" />
    </inertial>
  </link>
  <joint name="fr3v2_joint6" type="revolute">
    <origin rpy="1.570796326794897 0 0" xyz="0 0 0" />
    <parent link="fr3v2_link5" />
    <child link="fr3v2_link6" />
    <axis xyz="0 0 1" />
    <limit effort="12.0" lower="0.5445" upper="4.5169" velocity="4.18" />
    <safety_controller k_position="100.0" k_velocity="40.0" soft_lower_limit="0.5445" soft_upper_limit="4.5169" />
    <dynamics D="1" K="7000" damping="0.003" friction="0.2" mu_coulomb="0" mu_viscous="16" />
  </joint>
  
  <link name="fr3v2_link7">
    <inertial>
      <origin rpy="0 0 0" xyz="0.008204 0.001156 0.061016" />
      <mass value="0.682876" />
      <inertia ixx="0.000899" ixy="0.0" ixz="-1.3e-05" iyy="0.001099" iyz="-2.2e-05" izz="0.000702" />
    </inertial>
  </link>
  <joint name="fr3v2_joint7" type="revolute">
    <origin rpy="1.570796326794897 0 0" xyz="0.088 0 0" />
    <parent link="fr3v2_link6" />
    <child link="fr3v2_link7" />
    <axis xyz="0 0 1" />
    <limit effort="12.0" lower="-3.0159" upper="3.0159" velocity="5.26" />
    <safety_controller k_position="100.0" k_velocity="40.0" soft_lower_limit="-3.0159" soft_upper_limit="3.0159" />
    <dynamics D="1" K="7000" damping="0.003" friction="0.2" mu_coulomb="0" mu_viscous="16" />
  </joint>
  <link name="fr3v2_link8" />
  <joint name="fr3v2_joint8" type="fixed">
    <origin rpy="0 0 0" xyz="0 0 0.107" />
    <parent link="fr3v2_link7" />
    <child link="fr3v2_link8" />
  </joint>
  <joint name="fr3v2_hand_joint" type="fixed">
    <parent link="fr3v2_link8" />
    <child link="fr3v2_hand" />
    <origin rpy="0 0 -0.7853981633974483" xyz="0 0 0" />
  </joint>
  
  <link name="fr3v2_hand">
    <inertial>
      <origin rpy="0 0 0" xyz="-0.0000376 0.0119128 0.0207260" />
      <mass value="0.6544" />
      <inertia ixx="0.00186" ixy="0.0" ixz="0.0" iyy="0.0003" iyz="-2e-05" izz="0.00174" />
    </inertial>
  </link>
  
  <link name="fr3v2_hand_tcp" />
  <joint name="fr3v2_hand_tcp_joint" type="fixed">
    <origin rpy="0 0 0" xyz="0 0 0.1034" />
    <parent link="fr3v2_hand" />
    <child link="fr3v2_hand_tcp" />
  </joint>
  <link name="fr3v2_leftfinger">
    <inertial>
      <origin rpy="0 0 0" xyz="0 0.0152850 0.0219675" />
      <mass value="0.0291" />
      <inertia ixx="8.49e-06" ixy="0.0" ixz="0.0" iyy="8.53e-06" iyz="-1.06e-06" izz="1.77e-06" />
    </inertial>
  </link>
  <link name="fr3v2_rightfinger">
    <inertial>
      <origin rpy="0 0 0" xyz="0 0.0152850 0.0219675" />
      <mass value="0.0291" />
      <inertia ixx="8.49e-06" ixy="0.0" ixz="0.0" iyy="8.53e-06" iyz="-1.06e-06" izz="1.77e-06" />
    </inertial>
  </link>
  <joint name="fr3v2_finger_joint1" type="prismatic">
    <parent link="fr3v2_hand" />
    <child link="fr3v2_leftfinger" />
    <origin rpy="0 0 0" xyz="0 0 0.0584" />
    <axis xyz="0 1 0" />
    <limit effort="100" lower="0.0" upper="0.04" velocity="0.2" />
    <dynamics damping="0.3" />
  </joint>
  <joint name="fr3v2_finger_joint2" type="prismatic">
    <parent link="fr3v2_hand" />
    <child link="fr3v2_rightfinger" />
    <origin rpy="0 0 3.141592653589793" xyz="0 0 0.0584" />
    <axis xyz="0 1 0" />
    <limit effort="100" lower="0.0" upper="0.04" velocity="0.2" />
    <mimic joint="fr3v2_finger_joint1" />
    <dynamics damping="0.3" />
  </joint>
</robot>